2025-03-19 03:33:26,929 - CRITICAL - app.py:513 - Unexpected Error: 404 Not Found: The requested URL was not found on the server. If you entered the URL manually please check your spelling and try again.
Traceback (most recent call last):
  File "C:\Users\TUF\AppData\Roaming\Python\Python313\site-packages\flask\app.py", line 917, in full_dispatch_request
    rv = self.dispatch_request()
  File "C:\Users\TUF\AppData\Roaming\Python\Python313\site-packages\flask\app.py", line 891, in dispatch_request
    self.raise_routing_exception(req)
    ~~~~~~~~~~~~~~~~~~~~~~~~~~~~^^^^^
  File "C:\Users\TUF\AppData\Roaming\Python\Python313\site-packages\flask\app.py", line 500, in raise_routing_exception
    raise request.routing_exception  # type: ignore[misc]
    ^^^^^^^^^^^^^^^^^^^^^^^^^^^^^^^
  File "C:\Users\TUF\AppData\Roaming\Python\Python313\site-packages\flask\ctx.py", line 362, in match_request
    result = self.url_adapter.match(return_rule=True)  # type: ignore
  File "C:\Users\TUF\AppData\Roaming\Python\Python313\site-packages\werkzeug\routing\map.py", line 629, in match
    raise NotFound() from None
werkzeug.exceptions.NotFound: 404 Not Found: The requested URL was not found on the server. If you entered the URL manually please check your spelling and try again.
2025-03-19 03:33:26,934 - INFO - _internal.py:97 - 127.0.0.1 - - [19/Mar/2025 03:33:26] "[35m[1mGET /favicon.ico HTTP/1.1[0m" 500 -
2025-03-19 03:33:30,237 - INFO - _internal.py:97 - 127.0.0.1 - - [19/Mar/2025 03:33:30] "GET /chat HTTP/1.1" 200 -
2025-03-19 03:33:30,932 - CRITICAL - app.py:513 - Unexpected Error: 404 Not Found: The requested URL was not found on the server. If you entered the URL manually please check your spelling and try again.
Traceback (most recent call last):
  File "C:\Users\TUF\AppData\Roaming\Python\Python313\site-packages\flask\app.py", line 917, in full_dispatch_request
    rv = self.dispatch_request()
  File "C:\Users\TUF\AppData\Roaming\Python\Python313\site-packages\flask\app.py", line 891, in dispatch_request
    self.raise_routing_exception(req)
    ~~~~~~~~~~~~~~~~~~~~~~~~~~~~^^^^^
  File "C:\Users\TUF\AppData\Roaming\Python\Python313\site-packages\flask\app.py", line 500, in raise_routing_exception
    raise request.routing_exception  # type: ignore[misc]
    ^^^^^^^^^^^^^^^^^^^^^^^^^^^^^^^
  File "C:\Users\TUF\AppData\Roaming\Python\Python313\site-packages\flask\ctx.py", line 362, in match_request
    result = self.url_adapter.match(return_rule=True)  # type: ignore
  File "C:\Users\TUF\AppData\Roaming\Python\Python313\site-packages\werkzeug\routing\map.py", line 629, in match
    raise NotFound() from None
werkzeug.exceptions.NotFound: 404 Not Found: The requested URL was not found on the server. If you entered the URL manually please check your spelling and try again.
2025-03-19 03:33:30,935 - INFO - _internal.py:97 - 127.0.0.1 - - [19/Mar/2025 03:33:30] "[35m[1mGET /favicon.ico HTTP/1.1[0m" 500 -
2025-03-19 03:33:32,317 - INFO - _internal.py:97 - 127.0.0.1 - - [19/Mar/2025 03:33:32] "GET /select?message=à¸”à¸¹à¸”à¸§à¸‡à¸—à¸±à¹ˆà¸§à¹„à¸›&relationship_status= HTTP/1.1" 200 -
2025-03-19 03:33:32,508 - INFO - _internal.py:97 - 127.0.0.1 - - [19/Mar/2025 03:33:32] "[36mGET /static/images/inkcy_tarot.jpg HTTP/1.1[0m" 304 -
2025-03-19 03:33:32,522 - CRITICAL - app.py:513 - Unexpected Error: 404 Not Found: The requested URL was not found on the server. If you entered the URL manually please check your spelling and try again.
Traceback (most recent call last):
  File "C:\Users\TUF\AppData\Roaming\Python\Python313\site-packages\flask\app.py", line 917, in full_dispatch_request
    rv = self.dispatch_request()
  File "C:\Users\TUF\AppData\Roaming\Python\Python313\site-packages\flask\app.py", line 891, in dispatch_request
    self.raise_routing_exception(req)
    ~~~~~~~~~~~~~~~~~~~~~~~~~~~~^^^^^
  File "C:\Users\TUF\AppData\Roaming\Python\Python313\site-packages\flask\app.py", line 500, in raise_routing_exception
    raise request.routing_exception  # type: ignore[misc]
    ^^^^^^^^^^^^^^^^^^^^^^^^^^^^^^^
  File "C:\Users\TUF\AppData\Roaming\Python\Python313\site-packages\flask\ctx.py", line 362, in match_request
    result = self.url_adapter.match(return_rule=True)  # type: ignore
  File "C:\Users\TUF\AppData\Roaming\Python\Python313\site-packages\werkzeug\routing\map.py", line 629, in match
    raise NotFound() from None
werkzeug.exceptions.NotFound: 404 Not Found: The requested URL was not found on the server. If you entered the URL manually please check your spelling and try again.
2025-03-19 03:33:32,525 - INFO - _internal.py:97 - 127.0.0.1 - - [19/Mar/2025 03:33:32] "[35m[1mGET /favicon.ico HTTP/1.1[0m" 500 -
2025-03-19 03:33:36,382 - INFO - _internal.py:97 - 127.0.0.1 - - [19/Mar/2025 03:33:36] "[36mGET /static/images/the_hierophant.png HTTP/1.1[0m" 304 -
2025-03-19 03:33:37,200 - INFO - _internal.py:97 - 127.0.0.1 - - [19/Mar/2025 03:33:37] "GET /loading?message=à¸”à¸¹à¸”à¸§à¸‡à¸—à¸±à¹ˆà¸§à¹„à¸›&relationship_status=&card=The%20Hierophant&category=career HTTP/1.1" 200 -
2025-03-19 03:33:37,352 - CRITICAL - app.py:513 - Unexpected Error: 404 Not Found: The requested URL was not found on the server. If you entered the URL manually please check your spelling and try again.
Traceback (most recent call last):
  File "C:\Users\TUF\AppData\Roaming\Python\Python313\site-packages\flask\app.py", line 917, in full_dispatch_request
    rv = self.dispatch_request()
  File "C:\Users\TUF\AppData\Roaming\Python\Python313\site-packages\flask\app.py", line 891, in dispatch_request
    self.raise_routing_exception(req)
    ~~~~~~~~~~~~~~~~~~~~~~~~~~~~^^^^^
  File "C:\Users\TUF\AppData\Roaming\Python\Python313\site-packages\flask\app.py", line 500, in raise_routing_exception
    raise request.routing_exception  # type: ignore[misc]
    ^^^^^^^^^^^^^^^^^^^^^^^^^^^^^^^
  File "C:\Users\TUF\AppData\Roaming\Python\Python313\site-packages\flask\ctx.py", line 362, in match_request
    result = self.url_adapter.match(return_rule=True)  # type: ignore
  File "C:\Users\TUF\AppData\Roaming\Python\Python313\site-packages\werkzeug\routing\map.py", line 629, in match
    raise NotFound() from None
werkzeug.exceptions.NotFound: 404 Not Found: The requested URL was not found on the server. If you entered the URL manually please check your spelling and try again.
2025-03-19 03:33:37,355 - INFO - _internal.py:97 - 127.0.0.1 - - [19/Mar/2025 03:33:37] "[35m[1mGET /favicon.ico HTTP/1.1[0m" 500 -
2025-03-19 03:33:39,365 - ERROR - app.py:164 - GPT-2 à¸¥à¹‰à¸¡à¹€à¸«à¸¥à¸§: Input length of input_ids is 50, but `max_length` is set to 40. This can lead to unexpected behavior. You should consider increasing `max_length` or, better yet, setting `max_new_tokens`.
2025-03-19 03:33:39,367 - INFO - _internal.py:97 - 127.0.0.1 - - [19/Mar/2025 03:33:39] "GET /prediction?message=à¸”à¸¹à¸”à¸§à¸‡à¸—à¸±à¹ˆà¸§à¹„à¸›&relationship_status=&card=The%20Hierophant&category=career HTTP/1.1" 200 -
2025-03-19 03:33:39,489 - INFO - _internal.py:97 - 127.0.0.1 - - [19/Mar/2025 03:33:39] "[36mGET /static/images/the_hierophant.png HTTP/1.1[0m" 304 -
2025-03-19 03:33:39,494 - CRITICAL - app.py:513 - Unexpected Error: 404 Not Found: The requested URL was not found on the server. If you entered the URL manually please check your spelling and try again.
Traceback (most recent call last):
  File "C:\Users\TUF\AppData\Roaming\Python\Python313\site-packages\flask\app.py", line 917, in full_dispatch_request
    rv = self.dispatch_request()
  File "C:\Users\TUF\AppData\Roaming\Python\Python313\site-packages\flask\app.py", line 891, in dispatch_request
    self.raise_routing_exception(req)
    ~~~~~~~~~~~~~~~~~~~~~~~~~~~~^^^^^
  File "C:\Users\TUF\AppData\Roaming\Python\Python313\site-packages\flask\app.py", line 500, in raise_routing_exception
    raise request.routing_exception  # type: ignore[misc]
    ^^^^^^^^^^^^^^^^^^^^^^^^^^^^^^^
  File "C:\Users\TUF\AppData\Roaming\Python\Python313\site-packages\flask\ctx.py", line 362, in match_request
    result = self.url_adapter.match(return_rule=True)  # type: ignore
  File "C:\Users\TUF\AppData\Roaming\Python\Python313\site-packages\werkzeug\routing\map.py", line 629, in match
    raise NotFound() from None
werkzeug.exceptions.NotFound: 404 Not Found: The requested URL was not found on the server. If you entered the URL manually please check your spelling and try again.
2025-03-19 03:33:39,498 - INFO - _internal.py:97 - 127.0.0.1 - - [19/Mar/2025 03:33:39] "[35m[1mGET /favicon.ico HTTP/1.1[0m" 500 -
2025-03-19 03:33:41,829 - INFO - _internal.py:97 - 127.0.0.1 - - [19/Mar/2025 03:33:41] "GET /chat HTTP/1.1" 200 -
