2025-03-19 03:29:28,125 - CRITICAL - app.py:508 - Unexpected Error: 404 Not Found: The requested URL was not found on the server. If you entered the URL manually please check your spelling and try again.
Traceback (most recent call last):
  File "C:\Users\TUF\AppData\Roaming\Python\Python313\site-packages\flask\app.py", line 917, in full_dispatch_request
    rv = self.dispatch_request()
  File "C:\Users\TUF\AppData\Roaming\Python\Python313\site-packages\flask\app.py", line 891, in dispatch_request
    self.raise_routing_exception(req)
    ~~~~~~~~~~~~~~~~~~~~~~~~~~~~^^^^^
  File "C:\Users\TUF\AppData\Roaming\Python\Python313\site-packages\flask\app.py", line 500, in raise_routing_exception
    raise request.routing_exception  # type: ignore[misc]
    ^^^^^^^^^^^^^^^^^^^^^^^^^^^^^^^
  File "C:\Users\TUF\AppData\Roaming\Python\Python313\site-packages\flask\ctx.py", line 362, in match_request
    result = self.url_adapter.match(return_rule=True)  # type: ignore
  File "C:\Users\TUF\AppData\Roaming\Python\Python313\site-packages\werkzeug\routing\map.py", line 629, in match
    raise NotFound() from None
werkzeug.exceptions.NotFound: 404 Not Found: The requested URL was not found on the server. If you entered the URL manually please check your spelling and try again.
2025-03-19 03:29:28,131 - INFO - _internal.py:97 - 127.0.0.1 - - [19/Mar/2025 03:29:28] "[35m[1mGET /favicon.ico HTTP/1.1[0m" 500 -
2025-03-19 03:29:53,276 - INFO - _internal.py:97 - 127.0.0.1 - - [19/Mar/2025 03:29:53] "GET /loading?message=‡∏î‡∏π‡∏î‡∏ß‡∏á‡∏ó‡∏±‡πà‡∏ß‡πÑ‡∏õ&relationship_status=&card=The%20Emperor&category=career HTTP/1.1" 200 -
2025-03-19 03:29:53,528 - CRITICAL - app.py:508 - Unexpected Error: 404 Not Found: The requested URL was not found on the server. If you entered the URL manually please check your spelling and try again.
Traceback (most recent call last):
  File "C:\Users\TUF\AppData\Roaming\Python\Python313\site-packages\flask\app.py", line 917, in full_dispatch_request
    rv = self.dispatch_request()
  File "C:\Users\TUF\AppData\Roaming\Python\Python313\site-packages\flask\app.py", line 891, in dispatch_request
    self.raise_routing_exception(req)
    ~~~~~~~~~~~~~~~~~~~~~~~~~~~~^^^^^
  File "C:\Users\TUF\AppData\Roaming\Python\Python313\site-packages\flask\app.py", line 500, in raise_routing_exception
    raise request.routing_exception  # type: ignore[misc]
    ^^^^^^^^^^^^^^^^^^^^^^^^^^^^^^^
  File "C:\Users\TUF\AppData\Roaming\Python\Python313\site-packages\flask\ctx.py", line 362, in match_request
    result = self.url_adapter.match(return_rule=True)  # type: ignore
  File "C:\Users\TUF\AppData\Roaming\Python\Python313\site-packages\werkzeug\routing\map.py", line 629, in match
    raise NotFound() from None
werkzeug.exceptions.NotFound: 404 Not Found: The requested URL was not found on the server. If you entered the URL manually please check your spelling and try again.
2025-03-19 03:29:53,532 - INFO - _internal.py:97 - 127.0.0.1 - - [19/Mar/2025 03:29:53] "[35m[1mGET /favicon.ico HTTP/1.1[0m" 500 -
2025-03-19 03:29:55,534 - INFO - _internal.py:97 - 127.0.0.1 - - [19/Mar/2025 03:29:55] "GET /prediction?message=‡∏î‡∏π‡∏î‡∏ß‡∏á‡∏ó‡∏±‡πà‡∏ß‡πÑ‡∏õ&relationship_status=&card=The%20Emperor&category=career HTTP/1.1" 200 -
2025-03-19 03:29:55,647 - INFO - _internal.py:97 - 127.0.0.1 - - [19/Mar/2025 03:29:55] "[36mGET /static/images/the_emperor.png HTTP/1.1[0m" 304 -
2025-03-19 03:29:55,649 - CRITICAL - app.py:508 - Unexpected Error: 404 Not Found: The requested URL was not found on the server. If you entered the URL manually please check your spelling and try again.
Traceback (most recent call last):
  File "C:\Users\TUF\AppData\Roaming\Python\Python313\site-packages\flask\app.py", line 917, in full_dispatch_request
    rv = self.dispatch_request()
  File "C:\Users\TUF\AppData\Roaming\Python\Python313\site-packages\flask\app.py", line 891, in dispatch_request
    self.raise_routing_exception(req)
    ~~~~~~~~~~~~~~~~~~~~~~~~~~~~^^^^^
  File "C:\Users\TUF\AppData\Roaming\Python\Python313\site-packages\flask\app.py", line 500, in raise_routing_exception
    raise request.routing_exception  # type: ignore[misc]
    ^^^^^^^^^^^^^^^^^^^^^^^^^^^^^^^
  File "C:\Users\TUF\AppData\Roaming\Python\Python313\site-packages\flask\ctx.py", line 362, in match_request
    result = self.url_adapter.match(return_rule=True)  # type: ignore
  File "C:\Users\TUF\AppData\Roaming\Python\Python313\site-packages\werkzeug\routing\map.py", line 629, in match
    raise NotFound() from None
werkzeug.exceptions.NotFound: 404 Not Found: The requested URL was not found on the server. If you entered the URL manually please check your spelling and try again.
2025-03-19 03:29:55,654 - INFO - _internal.py:97 - 127.0.0.1 - - [19/Mar/2025 03:29:55] "[35m[1mGET /favicon.ico HTTP/1.1[0m" 500 -
2025-03-19 03:33:01,925 - INFO - app.py:62 - ‡πÇ‡∏´‡∏•‡∏î tarot_data_th.csv ‡∏™‡∏≥‡πÄ‡∏£‡πá‡∏à ‡∏à‡∏≥‡∏ô‡∏ß‡∏ô‡πÅ‡∏ñ‡∏ß: 176
2025-03-19 03:33:01,937 - INFO - _internal.py:97 - [31m[1mWARNING: This is a development server. Do not use it in a production deployment. Use a production WSGI server instead.[0m
 * Running on all addresses (0.0.0.0)
 * Running on http://127.0.0.1:5000
 * Running on http://172.20.10.5:5000
2025-03-19 03:33:01,937 - INFO - _internal.py:97 - [33mPress CTRL+C to quit[0m
2025-03-19 03:33:05,343 - INFO - app.py:101 - ‡πÉ‡∏ä‡πâ GPU ‡∏™‡∏≥‡∏´‡∏£‡∏±‡∏ö mBERT
2025-03-19 03:33:05,344 - INFO - app.py:104 - ‡πÇ‡∏´‡∏•‡∏î mBERT ‡∏™‡∏≥‡πÄ‡∏£‡πá‡∏à
2025-03-19 03:33:08,219 - INFO - app.py:101 - ‡πÉ‡∏ä‡πâ GPU ‡∏™‡∏≥‡∏´‡∏£‡∏±‡∏ö GPT-2
2025-03-19 03:33:08,219 - INFO - app.py:104 - ‡πÇ‡∏´‡∏•‡∏î GPT-2 ‡∏™‡∏≥‡πÄ‡∏£‡πá‡∏à
2025-03-19 03:33:08,932 - INFO - _internal.py:97 - 127.0.0.1 - - [19/Mar/2025 03:33:08] "GET / HTTP/1.1" 200 -
2025-03-19 03:33:09,119 - INFO - _internal.py:97 - 127.0.0.1 - - [19/Mar/2025 03:33:09] "[36mGET /static/images/inkcy_tarot.jpg HTTP/1.1[0m" 304 -
2025-03-19 03:33:09,126 - CRITICAL - app.py:513 - Unexpected Error: 404 Not Found: The requested URL was not found on the server. If you entered the URL manually please check your spelling and try again.
Traceback (most recent call last):
  File "C:\Users\TUF\AppData\Roaming\Python\Python313\site-packages\flask\app.py", line 917, in full_dispatch_request
    rv = self.dispatch_request()
  File "C:\Users\TUF\AppData\Roaming\Python\Python313\site-packages\flask\app.py", line 891, in dispatch_request
    self.raise_routing_exception(req)
    ~~~~~~~~~~~~~~~~~~~~~~~~~~~~^^^^^
  File "C:\Users\TUF\AppData\Roaming\Python\Python313\site-packages\flask\app.py", line 500, in raise_routing_exception
    raise request.routing_exception  # type: ignore[misc]
    ^^^^^^^^^^^^^^^^^^^^^^^^^^^^^^^
  File "C:\Users\TUF\AppData\Roaming\Python\Python313\site-packages\flask\ctx.py", line 362, in match_request
    result = self.url_adapter.match(return_rule=True)  # type: ignore
  File "C:\Users\TUF\AppData\Roaming\Python\Python313\site-packages\werkzeug\routing\map.py", line 629, in match
    raise NotFound() from None
werkzeug.exceptions.NotFound: 404 Not Found: The requested URL was not found on the server. If you entered the URL manually please check your spelling and try again.
2025-03-19 03:33:09,131 - INFO - _internal.py:97 - 127.0.0.1 - - [19/Mar/2025 03:33:09] "[35m[1mGET /favicon.ico HTTP/1.1[0m" 500 -
2025-03-19 03:33:10,878 - INFO - _internal.py:97 - 127.0.0.1 - - [19/Mar/2025 03:33:10] "GET /article HTTP/1.1" 200 -
2025-03-19 03:33:10,980 - INFO - _internal.py:97 - 127.0.0.1 - - [19/Mar/2025 03:33:10] "[36mGET /static/images/the_empress.png HTTP/1.1[0m" 304 -
2025-03-19 03:33:10,982 - INFO - _internal.py:97 - 127.0.0.1 - - [19/Mar/2025 03:33:10] "[36mGET /static/images/the_emperor.png HTTP/1.1[0m" 304 -
2025-03-19 03:33:10,985 - CRITICAL - app.py:513 - Unexpected Error: 404 Not Found: The requested URL was not found on the server. If you entered the URL manually please check your spelling and try again.
Traceback (most recent call last):
  File "C:\Users\TUF\AppData\Roaming\Python\Python313\site-packages\flask\app.py", line 917, in full_dispatch_request
    rv = self.dispatch_request()
  File "C:\Users\TUF\AppData\Roaming\Python\Python313\site-packages\flask\app.py", line 891, in dispatch_request
    self.raise_routing_exception(req)
    ~~~~~~~~~~~~~~~~~~~~~~~~~~~~^^^^^
  File "C:\Users\TUF\AppData\Roaming\Python\Python313\site-packages\flask\app.py", line 500, in raise_routing_exception
    raise request.routing_exception  # type: ignore[misc]
    ^^^^^^^^^^^^^^^^^^^^^^^^^^^^^^^
  File "C:\Users\TUF\AppData\Roaming\Python\Python313\site-packages\flask\ctx.py", line 362, in match_request
    result = self.url_adapter.match(return_rule=True)  # type: ignore
  File "C:\Users\TUF\AppData\Roaming\Python\Python313\site-packages\werkzeug\routing\map.py", line 629, in match
    raise NotFound() from None
werkzeug.exceptions.NotFound: 404 Not Found: The requested URL was not found on the server. If you entered the URL manually please check your spelling and try again.
2025-03-19 03:33:10,987 - INFO - _internal.py:97 - 127.0.0.1 - - [19/Mar/2025 03:33:10] "[36mGET /static/images/the_fool.png HTTP/1.1[0m" 304 -
2025-03-19 03:33:10,991 - INFO - _internal.py:97 - 127.0.0.1 - - [19/Mar/2025 03:33:10] "[36mGET /static/images/the_high_priestess.png HTTP/1.1[0m" 304 -
2025-03-19 03:33:10,992 - INFO - _internal.py:97 - 127.0.0.1 - - [19/Mar/2025 03:33:10] "[36mGET /static/images/the_magician.png HTTP/1.1[0m" 304 -
2025-03-19 03:33:10,992 - INFO - _internal.py:97 - 127.0.0.1 - - [19/Mar/2025 03:33:10] "[35m[1mGET /favicon.ico HTTP/1.1[0m" 500 -
2025-03-19 03:33:11,001 - INFO - _internal.py:97 - 127.0.0.1 - - [19/Mar/2025 03:33:11] "[36mGET /static/images/the_hierophant.png HTTP/1.1[0m" 304 -
